DEBUG:urllib3.connectionpool:Starting new HTTP connection (1): www.nemweb.com.au:80
DEBUG:urllib3.connectionpool:Starting new HTTP connection (1): www.nemweb.com.au:80
DEBUG:urllib3.connectionpool:Starting new HTTP connection (1): www.nemweb.com.au:80
DEBUG:urllib3.connectionpool:Starting new HTTP connection (1): www.nemweb.com.au:80
DEBUG:urllib3.connectionpool:Starting new HTTP connection (1): www.nemweb.com.au:80
DEBUG:urllib3.connectionpool:Starting new HTTP connection (1): www.nemweb.com.au:80
DEBUG:urllib3.connectionpool:Starting new HTTP connection (1): api.ceem.org.au:80
ERROR:__main__:HTTPConnectionPool(host='api.ceem.org.au', port=80): Max retries exceeded with url: /elec-tariffs/network (Caused by NewConnectionError('<urllib3.connection.HTTPConnection object at 0x000001B8E05D68D0>: Failed to establish a new connection: [Errno 11001] getaddrinfo failed'))
Traceback (most recent call last):
  File "C:\Users\user\.virtualenvs\venv\TDA_Python\lib\site-packages\urllib3\connection.py", line 159, in _new_conn
    (self._dns_host, self.port), self.timeout, **extra_kw)
  File "C:\Users\user\.virtualenvs\venv\TDA_Python\lib\site-packages\urllib3\util\connection.py", line 57, in create_connection
    for res in socket.getaddrinfo(host, port, family, socket.SOCK_STREAM):
  File "C:\Users\user\AppData\Local\Programs\Python\Python37\lib\socket.py", line 748, in getaddrinfo
    for res in _socket.getaddrinfo(host, port, family, type, proto, flags):
socket.gaierror: [Errno 11001] getaddrinfo failed

During handling of the above exception, another exception occurred:

Traceback (most recent call last):
  File "C:\Users\user\.virtualenvs\venv\TDA_Python\lib\site-packages\urllib3\connectionpool.py", line 600, in urlopen
    chunked=chunked)
  File "C:\Users\user\.virtualenvs\venv\TDA_Python\lib\site-packages\urllib3\connectionpool.py", line 354, in _make_request
    conn.request(method, url, **httplib_request_kw)
  File "C:\Users\user\AppData\Local\Programs\Python\Python37\lib\http\client.py", line 1229, in request
    self._send_request(method, url, body, headers, encode_chunked)
  File "C:\Users\user\AppData\Local\Programs\Python\Python37\lib\http\client.py", line 1275, in _send_request
    self.endheaders(body, encode_chunked=encode_chunked)
  File "C:\Users\user\AppData\Local\Programs\Python\Python37\lib\http\client.py", line 1224, in endheaders
    self._send_output(message_body, encode_chunked=encode_chunked)
  File "C:\Users\user\AppData\Local\Programs\Python\Python37\lib\http\client.py", line 1016, in _send_output
    self.send(msg)
  File "C:\Users\user\AppData\Local\Programs\Python\Python37\lib\http\client.py", line 956, in send
    self.connect()
  File "C:\Users\user\.virtualenvs\venv\TDA_Python\lib\site-packages\urllib3\connection.py", line 181, in connect
    conn = self._new_conn()
  File "C:\Users\user\.virtualenvs\venv\TDA_Python\lib\site-packages\urllib3\connection.py", line 168, in _new_conn
    self, "Failed to establish a new connection: %s" % e)
urllib3.exceptions.NewConnectionError: <urllib3.connection.HTTPConnection object at 0x000001B8E05D68D0>: Failed to establish a new connection: [Errno 11001] getaddrinfo failed

During handling of the above exception, another exception occurred:

Traceback (most recent call last):
  File "C:\Users\user\.virtualenvs\venv\TDA_Python\lib\site-packages\requests\adapters.py", line 449, in send
    timeout=timeout
  File "C:\Users\user\.virtualenvs\venv\TDA_Python\lib\site-packages\urllib3\connectionpool.py", line 638, in urlopen
    _stacktrace=sys.exc_info()[2])
  File "C:\Users\user\.virtualenvs\venv\TDA_Python\lib\site-packages\urllib3\util\retry.py", line 398, in increment
    raise MaxRetryError(_pool, url, error or ResponseError(cause))
urllib3.exceptions.MaxRetryError: HTTPConnectionPool(host='api.ceem.org.au', port=80): Max retries exceeded with url: /elec-tariffs/network (Caused by NewConnectionError('<urllib3.connection.HTTPConnection object at 0x000001B8E05D68D0>: Failed to establish a new connection: [Errno 11001] getaddrinfo failed'))

During handling of the above exception, another exception occurred:

Traceback (most recent call last):
  File "C:\Users\user\Documents\GitHub\TDA_Python\errors.py", line 29, in wrapper
    return func(*args, **kwargs)
  File "C:/Users/user/Documents/GitHub/TDA_Python/tda.py", line 661, in on_start_up
    start_up_procedures.update_tariffs()
  File "C:\Users\user\Documents\GitHub\TDA_Python\start_up_procedures.py", line 16, in update_tariffs
    network_verison = update_tariff_set('network')
  File "C:\Users\user\Documents\GitHub\TDA_Python\start_up_procedures.py", line 23, in update_tariff_set
    response = requests.get('http://api.ceem.org.au/elec-tariffs/{}'.format(type))
  File "C:\Users\user\.virtualenvs\venv\TDA_Python\lib\site-packages\requests\api.py", line 75, in get
    return request('get', url, params=params, **kwargs)
  File "C:\Users\user\.virtualenvs\venv\TDA_Python\lib\site-packages\requests\api.py", line 60, in request
    return session.request(method=method, url=url, **kwargs)
  File "C:\Users\user\.virtualenvs\venv\TDA_Python\lib\site-packages\requests\sessions.py", line 533, in request
    resp = self.send(prep, **send_kwargs)
  File "C:\Users\user\.virtualenvs\venv\TDA_Python\lib\site-packages\requests\sessions.py", line 646, in send
    r = adapter.send(request, **kwargs)
  File "C:\Users\user\.virtualenvs\venv\TDA_Python\lib\site-packages\requests\adapters.py", line 516, in send
    raise ConnectionError(e, request=request)
requests.exceptions.ConnectionError: HTTPConnectionPool(host='api.ceem.org.au', port=80): Max retries exceeded with url: /elec-tariffs/network (Caused by NewConnectionError('<urllib3.connection.HTTPConnection object at 0x000001B8E05D68D0>: Failed to establish a new connection: [Errno 11001] getaddrinfo failed'))
INFO:werkzeug: * Running on http://127.0.0.1:5000/ (Press CTRL+C to quit)
DEBUG:urllib3.connectionpool:Starting new HTTP connection (1): api.ceem.org.au:80
ERROR:__main__:HTTPConnectionPool(host='api.ceem.org.au', port=80): Max retries exceeded with url: /elec-tariffs/network (Caused by NewConnectionError('<urllib3.connection.HTTPConnection object at 0x000001B8D928A780>: Failed to establish a new connection: [Errno 11001] getaddrinfo failed'))
Traceback (most recent call last):
  File "C:\Users\user\.virtualenvs\venv\TDA_Python\lib\site-packages\urllib3\connection.py", line 159, in _new_conn
    (self._dns_host, self.port), self.timeout, **extra_kw)
  File "C:\Users\user\.virtualenvs\venv\TDA_Python\lib\site-packages\urllib3\util\connection.py", line 57, in create_connection
    for res in socket.getaddrinfo(host, port, family, socket.SOCK_STREAM):
  File "C:\Users\user\AppData\Local\Programs\Python\Python37\lib\socket.py", line 748, in getaddrinfo
    for res in _socket.getaddrinfo(host, port, family, type, proto, flags):
socket.gaierror: [Errno 11001] getaddrinfo failed

During handling of the above exception, another exception occurred:

Traceback (most recent call last):
  File "C:\Users\user\.virtualenvs\venv\TDA_Python\lib\site-packages\urllib3\connectionpool.py", line 600, in urlopen
    chunked=chunked)
  File "C:\Users\user\.virtualenvs\venv\TDA_Python\lib\site-packages\urllib3\connectionpool.py", line 354, in _make_request
    conn.request(method, url, **httplib_request_kw)
  File "C:\Users\user\AppData\Local\Programs\Python\Python37\lib\http\client.py", line 1229, in request
    self._send_request(method, url, body, headers, encode_chunked)
  File "C:\Users\user\AppData\Local\Programs\Python\Python37\lib\http\client.py", line 1275, in _send_request
    self.endheaders(body, encode_chunked=encode_chunked)
  File "C:\Users\user\AppData\Local\Programs\Python\Python37\lib\http\client.py", line 1224, in endheaders
    self._send_output(message_body, encode_chunked=encode_chunked)
  File "C:\Users\user\AppData\Local\Programs\Python\Python37\lib\http\client.py", line 1016, in _send_output
    self.send(msg)
  File "C:\Users\user\AppData\Local\Programs\Python\Python37\lib\http\client.py", line 956, in send
    self.connect()
  File "C:\Users\user\.virtualenvs\venv\TDA_Python\lib\site-packages\urllib3\connection.py", line 181, in connect
    conn = self._new_conn()
  File "C:\Users\user\.virtualenvs\venv\TDA_Python\lib\site-packages\urllib3\connection.py", line 168, in _new_conn
    self, "Failed to establish a new connection: %s" % e)
urllib3.exceptions.NewConnectionError: <urllib3.connection.HTTPConnection object at 0x000001B8D928A780>: Failed to establish a new connection: [Errno 11001] getaddrinfo failed

During handling of the above exception, another exception occurred:

Traceback (most recent call last):
  File "C:\Users\user\.virtualenvs\venv\TDA_Python\lib\site-packages\requests\adapters.py", line 449, in send
    timeout=timeout
  File "C:\Users\user\.virtualenvs\venv\TDA_Python\lib\site-packages\urllib3\connectionpool.py", line 638, in urlopen
    _stacktrace=sys.exc_info()[2])
  File "C:\Users\user\.virtualenvs\venv\TDA_Python\lib\site-packages\urllib3\util\retry.py", line 398, in increment
    raise MaxRetryError(_pool, url, error or ResponseError(cause))
urllib3.exceptions.MaxRetryError: HTTPConnectionPool(host='api.ceem.org.au', port=80): Max retries exceeded with url: /elec-tariffs/network (Caused by NewConnectionError('<urllib3.connection.HTTPConnection object at 0x000001B8D928A780>: Failed to establish a new connection: [Errno 11001] getaddrinfo failed'))

During handling of the above exception, another exception occurred:

Traceback (most recent call last):
  File "C:\Users\user\Documents\GitHub\TDA_Python\errors.py", line 12, in wrapper
    return func(*args, **kwargs)
  File "C:/Users/user/Documents/GitHub/TDA_Python/tda.py", line 538, in update_tariffs
    network_version, retail_version = start_up_procedures.update_tariffs()
  File "C:\Users\user\Documents\GitHub\TDA_Python\start_up_procedures.py", line 16, in update_tariffs
    network_verison = update_tariff_set('network')
  File "C:\Users\user\Documents\GitHub\TDA_Python\start_up_procedures.py", line 23, in update_tariff_set
    response = requests.get('http://api.ceem.org.au/elec-tariffs/{}'.format(type))
  File "C:\Users\user\.virtualenvs\venv\TDA_Python\lib\site-packages\requests\api.py", line 75, in get
    return request('get', url, params=params, **kwargs)
  File "C:\Users\user\.virtualenvs\venv\TDA_Python\lib\site-packages\requests\api.py", line 60, in request
    return session.request(method=method, url=url, **kwargs)
  File "C:\Users\user\.virtualenvs\venv\TDA_Python\lib\site-packages\requests\sessions.py", line 533, in request
    resp = self.send(prep, **send_kwargs)
  File "C:\Users\user\.virtualenvs\venv\TDA_Python\lib\site-packages\requests\sessions.py", line 646, in send
    r = adapter.send(request, **kwargs)
  File "C:\Users\user\.virtualenvs\venv\TDA_Python\lib\site-packages\requests\adapters.py", line 516, in send
    raise ConnectionError(e, request=request)
requests.exceptions.ConnectionError: HTTPConnectionPool(host='api.ceem.org.au', port=80): Max retries exceeded with url: /elec-tariffs/network (Caused by NewConnectionError('<urllib3.connection.HTTPConnection object at 0x000001B8D928A780>: Failed to establish a new connection: [Errno 11001] getaddrinfo failed'))
INFO:werkzeug:127.0.0.1 - - [05/Sep/2019 09:35:06] "POST /update_tariffs HTTP/1.1" 200 -
INFO:werkzeug:127.0.0.1 - - [05/Sep/2019 09:35:06] "GET /get_tariff_set_options/network HTTP/1.1" 200 -
INFO:werkzeug:127.0.0.1 - - [05/Sep/2019 09:35:06] "GET /get_tariff_set_options/retail HTTP/1.1" 200 -
INFO:werkzeug:127.0.0.1 - - [05/Sep/2019 09:35:06] "POST /get_active_tariff_version HTTP/1.1" 200 -
INFO:werkzeug:127.0.0.1 - - [05/Sep/2019 09:35:06] "POST /get_active_tariff_version HTTP/1.1" 200 -
INFO:werkzeug:127.0.0.1 - - [05/Sep/2019 09:45:02] "GET /get_demo_options/test_data HTTP/1.1" 200 -
INFO:werkzeug:127.0.0.1 - - [05/Sep/2019 09:45:03] "POST /filtered_load_data HTTP/1.1" 200 -
INFO:werkzeug:127.0.0.1 - - [05/Sep/2019 09:45:33] "POST /tariff_json HTTP/1.1" 200 -
INFO:werkzeug:127.0.0.1 - - [05/Sep/2019 09:45:34] "GET /get_case_default_name HTTP/1.1" 200 -
INFO:werkzeug:127.0.0.1 - - [05/Sep/2019 09:45:35] "POST /add_case HTTP/1.1" 200 -
INFO:werkzeug:127.0.0.1 - - [05/Sep/2019 09:45:35] "POST /get_dual_variable_chart HTTP/1.1" 200 -
INFO:werkzeug:127.0.0.1 - - [05/Sep/2019 09:45:35] "POST /get_single_case_chart HTTP/1.1" 200 -
INFO:werkzeug:127.0.0.1 - - [05/Sep/2019 09:45:35] "POST /get_case_tariff HTTP/1.1" 200 -
INFO:werkzeug:127.0.0.1 - - [05/Sep/2019 09:45:35] "POST /get_case_tariff HTTP/1.1" 200 -
INFO:werkzeug:127.0.0.1 - - [05/Sep/2019 09:45:35] "POST /get_case_load HTTP/1.1" 200 -
INFO:werkzeug:127.0.0.1 - - [05/Sep/2019 09:45:35] "POST /get_case_demo_options HTTP/1.1" 200 -
INFO:werkzeug:127.0.0.1 - - [05/Sep/2019 09:45:35] "POST /get_wholesale_price_info HTTP/1.1" 200 -
INFO:werkzeug:127.0.0.1 - - [05/Sep/2019 09:45:35] "POST /get_single_variable_chart HTTP/1.1" 200 -
INFO:werkzeug:127.0.0.1 - - [05/Sep/2019 09:46:34] "POST /save_project_as HTTP/1.1" 200 -
INFO:werkzeug:127.0.0.1 - - [05/Sep/2019 09:46:37] "POST /delete_case HTTP/1.1" 200 -
INFO:werkzeug:127.0.0.1 - - [05/Sep/2019 09:46:37] "POST /get_single_variable_chart HTTP/1.1" 200 -
INFO:werkzeug:127.0.0.1 - - [05/Sep/2019 09:46:37] "POST /get_dual_variable_chart HTTP/1.1" 200 -
INFO:werkzeug:127.0.0.1 - - [05/Sep/2019 09:46:37] "POST /get_single_case_chart HTTP/1.1" 200 -
INFO:werkzeug:127.0.0.1 - - [05/Sep/2019 09:46:40] "POST /restart_tool HTTP/1.1" 200 -
INFO:werkzeug:127.0.0.1 - - [05/Sep/2019 09:46:40] "GET / HTTP/1.1" 200 -
INFO:werkzeug:127.0.0.1 - - [05/Sep/2019 09:46:41] "GET /get_tariff_set_options/network HTTP/1.1" 200 -
INFO:werkzeug:127.0.0.1 - - [05/Sep/2019 09:46:41] "GET /get_tariff_set_options/retail HTTP/1.1" 200 -
INFO:werkzeug:127.0.0.1 - - [05/Sep/2019 09:46:41] "GET /load_names HTTP/1.1" 200 -
INFO:werkzeug:127.0.0.1 - - [05/Sep/2019 09:46:41] "POST /get_active_tariff_version HTTP/1.1" 200 -
INFO:werkzeug:127.0.0.1 - - [05/Sep/2019 09:46:41] "POST /get_active_tariff_version HTTP/1.1" 200 -
INFO:werkzeug:127.0.0.1 - - [05/Sep/2019 09:46:41] "GET /tariff_selectors HTTP/1.1" 200 -
INFO:werkzeug:127.0.0.1 - - [05/Sep/2019 09:46:41] "GET /tariff_selectors HTTP/1.1" 200 -
INFO:werkzeug:127.0.0.1 - - [05/Sep/2019 09:46:41] "POST /wholesale_price_options HTTP/1.1" 200 -
INFO:werkzeug:127.0.0.1 - - [05/Sep/2019 09:46:41] "POST /wholesale_prices HTTP/1.1" 200 -
INFO:werkzeug:127.0.0.1 - - [05/Sep/2019 09:46:41] "POST /tariff_options HTTP/1.1" 200 -
INFO:werkzeug:127.0.0.1 - - [05/Sep/2019 09:46:41] "POST /tariff_options HTTP/1.1" 200 -
INFO:werkzeug:127.0.0.1 - - [05/Sep/2019 09:46:56] "POST /load_project HTTP/1.1" 200 -
INFO:werkzeug:127.0.0.1 - - [05/Sep/2019 09:46:56] "POST /get_case_tariff HTTP/1.1" 200 -
INFO:werkzeug:127.0.0.1 - - [05/Sep/2019 09:46:56] "POST /get_case_tariff HTTP/1.1" 200 -
INFO:werkzeug:127.0.0.1 - - [05/Sep/2019 09:46:56] "POST /get_case_load HTTP/1.1" 200 -
INFO:werkzeug:127.0.0.1 - - [05/Sep/2019 09:46:56] "POST /get_case_demo_options HTTP/1.1" 200 -
INFO:werkzeug:127.0.0.1 - - [05/Sep/2019 09:46:56] "POST /get_wholesale_price_info HTTP/1.1" 200 -
INFO:werkzeug:127.0.0.1 - - [05/Sep/2019 09:46:56] "POST /get_single_variable_chart HTTP/1.1" 200 -
INFO:werkzeug:127.0.0.1 - - [05/Sep/2019 09:46:56] "POST /get_dual_variable_chart HTTP/1.1" 200 -
INFO:werkzeug:127.0.0.1 - - [05/Sep/2019 09:46:56] "POST /get_single_case_chart HTTP/1.1" 200 -
INFO:werkzeug:127.0.0.1 - - [05/Sep/2019 09:50:21] "GET /get_demo_options/test_data HTTP/1.1" 200 -
INFO:werkzeug:127.0.0.1 - - [05/Sep/2019 09:50:23] "POST /filtered_load_data HTTP/1.1" 200 -
